[2023-01-23T14:17:21.195+0000] {taskinstance.py:1083} INFO - Dependencies all met for <TaskInstance: data_extraction_and_loading_1.extract_data scheduled__2022-01-01T07:00:00+00:00 [queued]>
[2023-01-23T14:17:21.659+0000] {taskinstance.py:1083} INFO - Dependencies all met for <TaskInstance: data_extraction_and_loading_1.extract_data scheduled__2022-01-01T07:00:00+00:00 [queued]>
[2023-01-23T14:17:21.699+0000] {taskinstance.py:1279} INFO - 
--------------------------------------------------------------------------------
[2023-01-23T14:17:21.705+0000] {taskinstance.py:1280} INFO - Starting attempt 1 of 2
[2023-01-23T14:17:21.718+0000] {taskinstance.py:1281} INFO - 
--------------------------------------------------------------------------------
[2023-01-23T14:17:22.361+0000] {taskinstance.py:1300} INFO - Executing <Task(PythonOperator): extract_data> on 2022-01-01 07:00:00+00:00
[2023-01-23T14:17:22.418+0000] {standard_task_runner.py:55} INFO - Started process 987 to run task
[2023-01-23T14:17:22.483+0000] {standard_task_runner.py:82} INFO - Running: ['***', 'tasks', 'run', 'data_extraction_and_loading_1', 'extract_data', 'scheduled__2022-01-01T07:00:00+00:00', '--job-id', '11', '--raw', '--subdir', 'DAGS_FOLDER/pipeline.py', '--cfg-path', '/tmp/tmpzikw8soi']
[2023-01-23T14:17:22.508+0000] {standard_task_runner.py:83} INFO - Job 11: Subtask extract_data
[2023-01-23T14:17:22.574+0000] {logging_mixin.py:137} WARNING - /home/***/.local/lib/python3.7/site-packages/***/settings.py:249 DeprecationWarning: The sql_alchemy_conn option in [core] has been moved to the sql_alchemy_conn option in [database] - the old setting has been used, but please update your config.
[2023-01-23T14:17:22.677+0000] {logging_mixin.py:137} WARNING - /home/***/.local/lib/python3.7/site-packages/***/utils/sqlalchemy.py:124 DeprecationWarning: The sql_alchemy_conn option in [core] has been moved to the sql_alchemy_conn option in [database] - the old setting has been used, but please update your config.
[2023-01-23T14:17:22.775+0000] {task_command.py:388} INFO - Running <TaskInstance: data_extraction_and_loading_1.extract_data scheduled__2022-01-01T07:00:00+00:00 [running]> on host 1b696c32fad4
[2023-01-23T14:17:23.166+0000] {taskinstance.py:1509} INFO - Exporting the following env vars:
AIRFLOW_CTX_DAG_OWNER=abdessamad
AIRFLOW_CTX_DAG_ID=data_extraction_and_loading_1
AIRFLOW_CTX_TASK_ID=extract_data
AIRFLOW_CTX_EXECUTION_DATE=2022-01-01T07:00:00+00:00
AIRFLOW_CTX_TRY_NUMBER=1
AIRFLOW_CTX_DAG_RUN_ID=scheduled__2022-01-01T07:00:00+00:00
[2023-01-23T14:17:23.275+0000] {connectionpool.py:813} WARNING - Retrying (Retry(total=2, connect=None, read=None, redirect=None, status=None)) after connection broken by 'NewConnectionError('<urllib3.connection.HTTPConnection object at 0xffff83455110>: Failed to establish a new connection: [Errno 111] Connection refused')': /session
[2023-01-23T14:17:23.282+0000] {connectionpool.py:813} WARNING - Retrying (Retry(total=1, connect=None, read=None, redirect=None, status=None)) after connection broken by 'NewConnectionError('<urllib3.connection.HTTPConnection object at 0xffff83418190>: Failed to establish a new connection: [Errno 111] Connection refused')': /session
[2023-01-23T14:17:23.288+0000] {connectionpool.py:813} WARNING - Retrying (Retry(total=0, connect=None, read=None, redirect=None, status=None)) after connection broken by 'NewConnectionError('<urllib3.connection.HTTPConnection object at 0xffff834187d0>: Failed to establish a new connection: [Errno 111] Connection refused')': /session
[2023-01-23T14:17:23.308+0000] {taskinstance.py:1768} ERROR - Task failed with exception
Traceback (most recent call last):
  File "/home/airflow/.local/lib/python3.7/site-packages/urllib3/connection.py", line 175, in _new_conn
    (self._dns_host, self.port), self.timeout, **extra_kw
  File "/home/airflow/.local/lib/python3.7/site-packages/urllib3/util/connection.py", line 95, in create_connection
    raise err
  File "/home/airflow/.local/lib/python3.7/site-packages/urllib3/util/connection.py", line 85, in create_connection
    sock.connect(sa)
ConnectionRefusedError: [Errno 111] Connection refused

During handling of the above exception, another exception occurred:

Traceback (most recent call last):
  File "/home/airflow/.local/lib/python3.7/site-packages/urllib3/connectionpool.py", line 710, in urlopen
    chunked=chunked,
  File "/home/airflow/.local/lib/python3.7/site-packages/urllib3/connectionpool.py", line 398, in _make_request
    conn.request(method, url, **httplib_request_kw)
  File "/home/airflow/.local/lib/python3.7/site-packages/urllib3/connection.py", line 239, in request
    super(HTTPConnection, self).request(method, url, body=body, headers=headers)
  File "/usr/local/lib/python3.7/http/client.py", line 1281, in request
    self._send_request(method, url, body, headers, encode_chunked)
  File "/usr/local/lib/python3.7/http/client.py", line 1327, in _send_request
    self.endheaders(body, encode_chunked=encode_chunked)
  File "/usr/local/lib/python3.7/http/client.py", line 1276, in endheaders
    self._send_output(message_body, encode_chunked=encode_chunked)
  File "/usr/local/lib/python3.7/http/client.py", line 1036, in _send_output
    self.send(msg)
  File "/usr/local/lib/python3.7/http/client.py", line 976, in send
    self.connect()
  File "/home/airflow/.local/lib/python3.7/site-packages/urllib3/connection.py", line 205, in connect
    conn = self._new_conn()
  File "/home/airflow/.local/lib/python3.7/site-packages/urllib3/connection.py", line 187, in _new_conn
    self, "Failed to establish a new connection: %s" % e
urllib3.exceptions.NewConnectionError: <urllib3.connection.HTTPConnection object at 0xffff83418d10>: Failed to establish a new connection: [Errno 111] Connection refused

During handling of the above exception, another exception occurred:

Traceback (most recent call last):
  File "/home/airflow/.local/lib/python3.7/site-packages/airflow/operators/python.py", line 175, in execute
    return_value = self.execute_callable()
  File "/home/airflow/.local/lib/python3.7/site-packages/airflow/operators/python.py", line 192, in execute_callable
    return self.python_callable(*self.op_args, **self.op_kwargs)
  File "/opt/airflow/dags/pipeline.py", line 9, in extract_data
    data_extractor = DataExtractor(remote_url="http://localhost:4444")
  File "/opt/airflow/dags/helpers.py", line 27, in __init__
    self.webdriver = webdriver.Remote(command_executor=remote_url, options=options)
  File "/home/airflow/.local/lib/python3.7/site-packages/selenium/webdriver/remote/webdriver.py", line 286, in __init__
    self.start_session(capabilities, browser_profile)
  File "/home/airflow/.local/lib/python3.7/site-packages/selenium/webdriver/remote/webdriver.py", line 378, in start_session
    response = self.execute(Command.NEW_SESSION, parameters)
  File "/home/airflow/.local/lib/python3.7/site-packages/selenium/webdriver/remote/webdriver.py", line 438, in execute
    response = self.command_executor.execute(driver_command, params)
  File "/home/airflow/.local/lib/python3.7/site-packages/selenium/webdriver/remote/remote_connection.py", line 290, in execute
    return self._request(command_info[0], url, body=data)
  File "/home/airflow/.local/lib/python3.7/site-packages/selenium/webdriver/remote/remote_connection.py", line 311, in _request
    response = self._conn.request(method, url, body=body, headers=headers)
  File "/home/airflow/.local/lib/python3.7/site-packages/urllib3/request.py", line 79, in request
    method, url, fields=fields, headers=headers, **urlopen_kw
  File "/home/airflow/.local/lib/python3.7/site-packages/urllib3/request.py", line 170, in request_encode_body
    return self.urlopen(method, url, **extra_kw)
  File "/home/airflow/.local/lib/python3.7/site-packages/urllib3/poolmanager.py", line 376, in urlopen
    response = conn.urlopen(method, u.request_uri, **kw)
  File "/home/airflow/.local/lib/python3.7/site-packages/urllib3/connectionpool.py", line 828, in urlopen
    **response_kw
  File "/home/airflow/.local/lib/python3.7/site-packages/urllib3/connectionpool.py", line 828, in urlopen
    **response_kw
  File "/home/airflow/.local/lib/python3.7/site-packages/urllib3/connectionpool.py", line 828, in urlopen
    **response_kw
  File "/home/airflow/.local/lib/python3.7/site-packages/urllib3/connectionpool.py", line 788, in urlopen
    method, url, error=e, _pool=self, _stacktrace=sys.exc_info()[2]
  File "/home/airflow/.local/lib/python3.7/site-packages/urllib3/util/retry.py", line 592, in increment
    raise MaxRetryError(_pool, url, error or ResponseError(cause))
urllib3.exceptions.MaxRetryError: HTTPConnectionPool(host='localhost', port=4444): Max retries exceeded with url: /session (Caused by NewConnectionError('<urllib3.connection.HTTPConnection object at 0xffff83418d10>: Failed to establish a new connection: [Errno 111] Connection refused'))
[2023-01-23T14:17:23.386+0000] {taskinstance.py:1323} INFO - Marking task as UP_FOR_RETRY. dag_id=data_extraction_and_loading_1, task_id=extract_data, execution_date=20220101T070000, start_date=20230123T141721, end_date=20230123T141723
[2023-01-23T14:17:23.831+0000] {standard_task_runner.py:105} ERROR - Failed to execute job 11 for task extract_data (HTTPConnectionPool(host='localhost', port=4444): Max retries exceeded with url: /session (Caused by NewConnectionError('<urllib3.connection.HTTPConnection object at 0xffff83418d10>: Failed to establish a new connection: [Errno 111] Connection refused')); 987)
[2023-01-23T14:17:24.012+0000] {local_task_job.py:208} INFO - Task exited with return code 1
[2023-01-23T14:17:24.249+0000] {taskinstance.py:2578} INFO - 0 downstream tasks scheduled from follow-on schedule check
