[2023-01-29T15:36:36.564+0000] {taskinstance.py:1083} INFO - Dependencies all met for <TaskInstance: data_pipeline.transform_data manual__2023-01-29T15:31:27.853762+00:00 [queued]>
[2023-01-29T15:36:36.571+0000] {taskinstance.py:1083} INFO - Dependencies all met for <TaskInstance: data_pipeline.transform_data manual__2023-01-29T15:31:27.853762+00:00 [queued]>
[2023-01-29T15:36:36.573+0000] {taskinstance.py:1279} INFO - 
--------------------------------------------------------------------------------
[2023-01-29T15:36:36.573+0000] {taskinstance.py:1280} INFO - Starting attempt 1 of 3
[2023-01-29T15:36:36.574+0000] {taskinstance.py:1281} INFO - 
--------------------------------------------------------------------------------
[2023-01-29T15:36:36.582+0000] {taskinstance.py:1300} INFO - Executing <Task(PythonOperator): transform_data> on 2023-01-29 15:31:27.853762+00:00
[2023-01-29T15:36:36.603+0000] {standard_task_runner.py:55} INFO - Started process 1030 to run task
[2023-01-29T15:36:36.607+0000] {standard_task_runner.py:82} INFO - Running: ['***', 'tasks', 'run', 'data_pipeline', 'transform_data', 'manual__2023-01-29T15:31:27.853762+00:00', '--job-id', '94', '--raw', '--subdir', 'DAGS_FOLDER/etl_dag.py', '--cfg-path', '/tmp/tmpejj3iaj9']
[2023-01-29T15:36:36.611+0000] {standard_task_runner.py:83} INFO - Job 94: Subtask transform_data
[2023-01-29T15:36:36.633+0000] {logging_mixin.py:137} WARNING - /home/***/.local/lib/python3.7/site-packages/***/settings.py:249 DeprecationWarning: The sql_alchemy_conn option in [core] has been moved to the sql_alchemy_conn option in [database] - the old setting has been used, but please update your config.
[2023-01-29T15:36:36.680+0000] {task_command.py:388} INFO - Running <TaskInstance: data_pipeline.transform_data manual__2023-01-29T15:31:27.853762+00:00 [running]> on host e0a1e7e3563d
[2023-01-29T15:36:36.740+0000] {taskinstance.py:1509} INFO - Exporting the following env vars:
AIRFLOW_CTX_DAG_OWNER=abdessamad
AIRFLOW_CTX_DAG_ID=data_pipeline
AIRFLOW_CTX_TASK_ID=transform_data
AIRFLOW_CTX_EXECUTION_DATE=2023-01-29T15:31:27.853762+00:00
AIRFLOW_CTX_TRY_NUMBER=1
AIRFLOW_CTX_DAG_RUN_ID=manual__2023-01-29T15:31:27.853762+00:00
[2023-01-29T15:37:06.835+0000] {taskinstance.py:1768} ERROR - Task failed with exception
Traceback (most recent call last):
  File "/home/airflow/.local/lib/python3.7/site-packages/airflow/operators/python.py", line 175, in execute
    return_value = self.execute_callable()
  File "/home/airflow/.local/lib/python3.7/site-packages/airflow/operators/python.py", line 192, in execute_callable
    return self.python_callable(*self.op_args, **self.op_kwargs)
  File "/opt/airflow/dags/etl_dag.py", line 46, in transform_data
    raw_data = data_extractor.view_docs(collection_name=temp_collection_name_1)
  File "/opt/airflow/dags/etl.py", line 212, in view_docs
    return list(collection.find())
  File "/home/airflow/.local/lib/python3.7/site-packages/pymongo/cursor.py", line 1248, in next
    if len(self.__data) or self._refresh():
  File "/home/airflow/.local/lib/python3.7/site-packages/pymongo/cursor.py", line 1139, in _refresh
    self.__session = self.__collection.database.client._ensure_session()
  File "/home/airflow/.local/lib/python3.7/site-packages/pymongo/mongo_client.py", line 1740, in _ensure_session
    return self.__start_session(True, causal_consistency=False)
  File "/home/airflow/.local/lib/python3.7/site-packages/pymongo/mongo_client.py", line 1685, in __start_session
    self._topology._check_implicit_session_support()
  File "/home/airflow/.local/lib/python3.7/site-packages/pymongo/topology.py", line 538, in _check_implicit_session_support
    self._check_session_support()
  File "/home/airflow/.local/lib/python3.7/site-packages/pymongo/topology.py", line 555, in _check_session_support
    readable_server_selector, self.get_server_selection_timeout(), None
  File "/home/airflow/.local/lib/python3.7/site-packages/pymongo/topology.py", line 240, in _select_servers_loop
    % (self._error_message(selector), timeout, self.description)
pymongo.errors.ServerSelectionTimeoutError: mongo_db:27017: [Errno -2] Name or service not known, Timeout: 30s, Topology Description: <TopologyDescription id: 63d692843c96e7e077228066, topology_type: Unknown, servers: [<ServerDescription ('mongo_db', 27017) server_type: Unknown, rtt: None, error=AutoReconnect('mongo_db:27017: [Errno -2] Name or service not known')>]>
[2023-01-29T15:37:06.937+0000] {taskinstance.py:1323} INFO - Marking task as UP_FOR_RETRY. dag_id=data_pipeline, task_id=transform_data, execution_date=20230129T153127, start_date=20230129T153636, end_date=20230129T153706
[2023-01-29T15:37:07.005+0000] {standard_task_runner.py:105} ERROR - Failed to execute job 94 for task transform_data (mongo_db:27017: [Errno -2] Name or service not known, Timeout: 30s, Topology Description: <TopologyDescription id: 63d692843c96e7e077228066, topology_type: Unknown, servers: [<ServerDescription ('mongo_db', 27017) server_type: Unknown, rtt: None, error=AutoReconnect('mongo_db:27017: [Errno -2] Name or service not known')>]>; 1030)
[2023-01-29T15:37:07.169+0000] {local_task_job.py:208} INFO - Task exited with return code 1
[2023-01-29T15:37:07.312+0000] {taskinstance.py:2578} INFO - 0 downstream tasks scheduled from follow-on schedule check
