[2023-01-29T20:02:59.226+0000] {taskinstance.py:1083} INFO - Dependencies all met for <TaskInstance: data_pipeline.extract_data manual__2023-01-29T20:02:50.498870+00:00 [queued]>
[2023-01-29T20:02:59.237+0000] {taskinstance.py:1083} INFO - Dependencies all met for <TaskInstance: data_pipeline.extract_data manual__2023-01-29T20:02:50.498870+00:00 [queued]>
[2023-01-29T20:02:59.237+0000] {taskinstance.py:1279} INFO - 
--------------------------------------------------------------------------------
[2023-01-29T20:02:59.237+0000] {taskinstance.py:1280} INFO - Starting attempt 1 of 3
[2023-01-29T20:02:59.237+0000] {taskinstance.py:1281} INFO - 
--------------------------------------------------------------------------------
[2023-01-29T20:02:59.254+0000] {taskinstance.py:1300} INFO - Executing <Task(PythonOperator): extract_data> on 2023-01-29 20:02:50.498870+00:00
[2023-01-29T20:02:59.264+0000] {standard_task_runner.py:55} INFO - Started process 764 to run task
[2023-01-29T20:02:59.269+0000] {standard_task_runner.py:82} INFO - Running: ['***', 'tasks', 'run', 'data_pipeline', 'extract_data', 'manual__2023-01-29T20:02:50.498870+00:00', '--job-id', '6', '--raw', '--subdir', 'DAGS_FOLDER/etl_dag.py', '--cfg-path', '/tmp/tmpysyim2l6']
[2023-01-29T20:02:59.272+0000] {standard_task_runner.py:83} INFO - Job 6: Subtask extract_data
[2023-01-29T20:02:59.299+0000] {logging_mixin.py:137} WARNING - /home/***/.local/lib/python3.7/site-packages/***/settings.py:249 DeprecationWarning: The sql_alchemy_conn option in [core] has been moved to the sql_alchemy_conn option in [database] - the old setting has been used, but please update your config.
[2023-01-29T20:02:59.357+0000] {task_command.py:388} INFO - Running <TaskInstance: data_pipeline.extract_data manual__2023-01-29T20:02:50.498870+00:00 [running]> on host 84fb6dd1372f
[2023-01-29T20:02:59.446+0000] {taskinstance.py:1509} INFO - Exporting the following env vars:
AIRFLOW_CTX_DAG_OWNER=abdessamad
AIRFLOW_CTX_DAG_ID=data_pipeline
AIRFLOW_CTX_TASK_ID=extract_data
AIRFLOW_CTX_EXECUTION_DATE=2023-01-29T20:02:50.498870+00:00
AIRFLOW_CTX_TRY_NUMBER=1
AIRFLOW_CTX_DAG_RUN_ID=manual__2023-01-29T20:02:50.498870+00:00
[2023-01-29T20:03:30.512+0000] {etl.py:120} ERROR - Error
[2023-01-29T20:03:30.565+0000] {etl.py:120} ERROR - Error
[2023-01-29T20:03:30.626+0000] {etl.py:120} ERROR - Error
[2023-01-29T20:03:30.717+0000] {etl.py:120} ERROR - Error
[2023-01-29T20:03:30.830+0000] {etl.py:120} ERROR - Error
[2023-01-29T20:04:01.075+0000] {logging_mixin.py:137} INFO - mongo_db:27017: [Errno -3] Temporary failure in name resolution, Timeout: 30s, Topology Description: <TopologyDescription id: 63d6d0f31727c81e412f97ca, topology_type: Unknown, servers: [<ServerDescription ('mongo_db', 27017) server_type: Unknown, rtt: None, error=AutoReconnect('mongo_db:27017: [Errno -3] Temporary failure in name resolution')>]>
[2023-01-29T20:04:31.191+0000] {logging_mixin.py:137} INFO - mongo_db:27017: [Errno -3] Temporary failure in name resolution, Timeout: 30s, Topology Description: <TopologyDescription id: 63d6d0f31727c81e412f97ca, topology_type: Unknown, servers: [<ServerDescription ('mongo_db', 27017) server_type: Unknown, rtt: None, error=AutoReconnect('mongo_db:27017: [Errno -3] Temporary failure in name resolution')>]>
[2023-01-29T20:05:01.328+0000] {logging_mixin.py:137} INFO - mongo_db:27017: [Errno -3] Temporary failure in name resolution, Timeout: 30s, Topology Description: <TopologyDescription id: 63d6d0f31727c81e412f97ca, topology_type: Unknown, servers: [<ServerDescription ('mongo_db', 27017) server_type: Unknown, rtt: None, error=AutoReconnect('mongo_db:27017: [Errno -3] Temporary failure in name resolution')>]>
[2023-01-29T20:05:31.510+0000] {logging_mixin.py:137} INFO - mongo_db:27017: [Errno -3] Temporary failure in name resolution, Timeout: 30s, Topology Description: <TopologyDescription id: 63d6d0f31727c81e412f97ca, topology_type: Unknown, servers: [<ServerDescription ('mongo_db', 27017) server_type: Unknown, rtt: None, error=AutoReconnect('mongo_db:27017: [Errno -3] Temporary failure in name resolution')>]>
[2023-01-29T20:06:01.588+0000] {logging_mixin.py:137} INFO - mongo_db:27017: [Errno -3] Temporary failure in name resolution, Timeout: 30s, Topology Description: <TopologyDescription id: 63d6d0f31727c81e412f97ca, topology_type: Unknown, servers: [<ServerDescription ('mongo_db', 27017) server_type: Unknown, rtt: None, error=AutoReconnect('mongo_db:27017: [Errno -3] Temporary failure in name resolution')>]>
[2023-01-29T20:06:31.788+0000] {logging_mixin.py:137} INFO - mongo_db:27017: [Errno -3] Temporary failure in name resolution, Timeout: 30s, Topology Description: <TopologyDescription id: 63d6d0f31727c81e412f97ca, topology_type: Unknown, servers: [<ServerDescription ('mongo_db', 27017) server_type: Unknown, rtt: None, error=AutoReconnect('mongo_db:27017: [Errno -3] Temporary failure in name resolution')>]>
[2023-01-29T20:07:02.034+0000] {logging_mixin.py:137} INFO - mongo_db:27017: [Errno -3] Temporary failure in name resolution, Timeout: 30s, Topology Description: <TopologyDescription id: 63d6d0f31727c81e412f97ca, topology_type: Unknown, servers: [<ServerDescription ('mongo_db', 27017) server_type: Unknown, rtt: None, error=AutoReconnect('mongo_db:27017: [Errno -3] Temporary failure in name resolution')>]>
[2023-01-29T20:07:32.182+0000] {logging_mixin.py:137} INFO - mongo_db:27017: [Errno -3] Temporary failure in name resolution, Timeout: 30s, Topology Description: <TopologyDescription id: 63d6d0f31727c81e412f97ca, topology_type: Unknown, servers: [<ServerDescription ('mongo_db', 27017) server_type: Unknown, rtt: None, error=AutoReconnect('mongo_db:27017: [Errno -3] Temporary failure in name resolution')>]>
[2023-01-29T20:08:02.298+0000] {logging_mixin.py:137} INFO - mongo_db:27017: [Errno -3] Temporary failure in name resolution, Timeout: 30s, Topology Description: <TopologyDescription id: 63d6d0f31727c81e412f97ca, topology_type: Unknown, servers: [<ServerDescription ('mongo_db', 27017) server_type: Unknown, rtt: None, error=AutoReconnect('mongo_db:27017: [Errno -3] Temporary failure in name resolution')>]>
[2023-01-29T20:08:32.420+0000] {logging_mixin.py:137} INFO - mongo_db:27017: [Errno -3] Temporary failure in name resolution, Timeout: 30s, Topology Description: <TopologyDescription id: 63d6d0f31727c81e412f97ca, topology_type: Unknown, servers: [<ServerDescription ('mongo_db', 27017) server_type: Unknown, rtt: None, error=AutoReconnect('mongo_db:27017: [Errno -3] Temporary failure in name resolution')>]>
[2023-01-29T20:24:10.721+0000] {connectionpool.py:813} WARNING - Retrying (Retry(total=2, connect=None, read=None, redirect=None, status=None)) after connection broken by 'ReadTimeoutError("HTTPConnectionPool(host='20.224.70.229', port=4444): Read timed out. (read timeout=None)")': /session/954bf311bdccb396b3ffa1287c5d8c37/window
[2023-01-29T20:24:10.775+0000] {python.py:177} INFO - Done. Returned value was: None
[2023-01-29T20:24:10.791+0000] {taskinstance.py:1323} INFO - Marking task as SUCCESS. dag_id=data_pipeline, task_id=extract_data, execution_date=20230129T200250, start_date=20230129T200259, end_date=20230129T202410
[2023-01-29T20:24:10.834+0000] {local_task_job.py:208} INFO - Task exited with return code 0
[2023-01-29T20:24:10.941+0000] {taskinstance.py:2578} INFO - 1 downstream tasks scheduled from follow-on schedule check
