[2023-01-23T14:30:24.585+0000] {taskinstance.py:1083} INFO - Dependencies all met for <TaskInstance: data_extraction_and_loading_3.extract_data scheduled__2022-01-24T00:00:00+00:00 [queued]>
[2023-01-23T14:30:24.665+0000] {taskinstance.py:1083} INFO - Dependencies all met for <TaskInstance: data_extraction_and_loading_3.extract_data scheduled__2022-01-24T00:00:00+00:00 [queued]>
[2023-01-23T14:30:24.667+0000] {taskinstance.py:1279} INFO - 
--------------------------------------------------------------------------------
[2023-01-23T14:30:24.668+0000] {taskinstance.py:1280} INFO - Starting attempt 1 of 2
[2023-01-23T14:30:24.673+0000] {taskinstance.py:1281} INFO - 
--------------------------------------------------------------------------------
[2023-01-23T14:30:24.918+0000] {taskinstance.py:1300} INFO - Executing <Task(PythonOperator): extract_data> on 2022-01-24 00:00:00+00:00
[2023-01-23T14:30:25.157+0000] {standard_task_runner.py:55} INFO - Started process 1506 to run task
[2023-01-23T14:30:25.231+0000] {standard_task_runner.py:82} INFO - Running: ['***', 'tasks', 'run', 'data_extraction_and_loading_3', 'extract_data', 'scheduled__2022-01-24T00:00:00+00:00', '--job-id', '69', '--raw', '--subdir', 'DAGS_FOLDER/pipeline.py', '--cfg-path', '/tmp/tmpxd0ojkev']
[2023-01-23T14:30:25.297+0000] {standard_task_runner.py:83} INFO - Job 69: Subtask extract_data
[2023-01-23T14:30:25.445+0000] {logging_mixin.py:137} WARNING - /home/***/.local/lib/python3.7/site-packages/***/settings.py:249 DeprecationWarning: The sql_alchemy_conn option in [core] has been moved to the sql_alchemy_conn option in [database] - the old setting has been used, but please update your config.
[2023-01-23T14:30:25.601+0000] {logging_mixin.py:137} WARNING - /home/***/.local/lib/python3.7/site-packages/***/utils/sqlalchemy.py:124 DeprecationWarning: The sql_alchemy_conn option in [core] has been moved to the sql_alchemy_conn option in [database] - the old setting has been used, but please update your config.
[2023-01-23T14:30:25.800+0000] {task_command.py:388} INFO - Running <TaskInstance: data_extraction_and_loading_3.extract_data scheduled__2022-01-24T00:00:00+00:00 [running]> on host 1b696c32fad4
[2023-01-23T14:30:27.915+0000] {taskinstance.py:1509} INFO - Exporting the following env vars:
AIRFLOW_CTX_DAG_OWNER=abdessamad
AIRFLOW_CTX_DAG_ID=data_extraction_and_loading_3
AIRFLOW_CTX_TASK_ID=extract_data
AIRFLOW_CTX_EXECUTION_DATE=2022-01-24T00:00:00+00:00
AIRFLOW_CTX_TRY_NUMBER=1
AIRFLOW_CTX_DAG_RUN_ID=scheduled__2022-01-24T00:00:00+00:00
[2023-01-23T14:35:02.907+0000] {taskinstance.py:1768} ERROR - Task failed with exception
Traceback (most recent call last):
  File "/home/airflow/.local/lib/python3.7/site-packages/urllib3/connectionpool.py", line 710, in urlopen
    chunked=chunked,
  File "/home/airflow/.local/lib/python3.7/site-packages/urllib3/connectionpool.py", line 449, in _make_request
    six.raise_from(e, None)
  File "<string>", line 3, in raise_from
  File "/home/airflow/.local/lib/python3.7/site-packages/urllib3/connectionpool.py", line 444, in _make_request
    httplib_response = conn.getresponse()
  File "/usr/local/lib/python3.7/http/client.py", line 1373, in getresponse
    response.begin()
  File "/usr/local/lib/python3.7/http/client.py", line 319, in begin
    version, status, reason = self._read_status()
  File "/usr/local/lib/python3.7/http/client.py", line 288, in _read_status
    raise RemoteDisconnected("Remote end closed connection without"
http.client.RemoteDisconnected: Remote end closed connection without response

During handling of the above exception, another exception occurred:

Traceback (most recent call last):
  File "/home/airflow/.local/lib/python3.7/site-packages/airflow/operators/python.py", line 175, in execute
    return_value = self.execute_callable()
  File "/home/airflow/.local/lib/python3.7/site-packages/airflow/operators/python.py", line 192, in execute_callable
    return self.python_callable(*self.op_args, **self.op_kwargs)
  File "/opt/airflow/dags/pipeline.py", line 9, in extract_data
    data_extractor = DataExtractor(remote_url="http://20.224.70.229:4444")
  File "/opt/airflow/dags/helpers.py", line 27, in __init__
    self.webdriver = webdriver.Remote(command_executor=remote_url, options=options)
  File "/home/airflow/.local/lib/python3.7/site-packages/selenium/webdriver/remote/webdriver.py", line 286, in __init__
    self.start_session(capabilities, browser_profile)
  File "/home/airflow/.local/lib/python3.7/site-packages/selenium/webdriver/remote/webdriver.py", line 378, in start_session
    response = self.execute(Command.NEW_SESSION, parameters)
  File "/home/airflow/.local/lib/python3.7/site-packages/selenium/webdriver/remote/webdriver.py", line 438, in execute
    response = self.command_executor.execute(driver_command, params)
  File "/home/airflow/.local/lib/python3.7/site-packages/selenium/webdriver/remote/remote_connection.py", line 290, in execute
    return self._request(command_info[0], url, body=data)
  File "/home/airflow/.local/lib/python3.7/site-packages/selenium/webdriver/remote/remote_connection.py", line 311, in _request
    response = self._conn.request(method, url, body=body, headers=headers)
  File "/home/airflow/.local/lib/python3.7/site-packages/urllib3/request.py", line 79, in request
    method, url, fields=fields, headers=headers, **urlopen_kw
  File "/home/airflow/.local/lib/python3.7/site-packages/urllib3/request.py", line 170, in request_encode_body
    return self.urlopen(method, url, **extra_kw)
  File "/home/airflow/.local/lib/python3.7/site-packages/urllib3/poolmanager.py", line 376, in urlopen
    response = conn.urlopen(method, u.request_uri, **kw)
  File "/home/airflow/.local/lib/python3.7/site-packages/urllib3/connectionpool.py", line 788, in urlopen
    method, url, error=e, _pool=self, _stacktrace=sys.exc_info()[2]
  File "/home/airflow/.local/lib/python3.7/site-packages/urllib3/util/retry.py", line 550, in increment
    raise six.reraise(type(error), error, _stacktrace)
  File "/home/airflow/.local/lib/python3.7/site-packages/urllib3/packages/six.py", line 769, in reraise
    raise value.with_traceback(tb)
  File "/home/airflow/.local/lib/python3.7/site-packages/urllib3/connectionpool.py", line 710, in urlopen
    chunked=chunked,
  File "/home/airflow/.local/lib/python3.7/site-packages/urllib3/connectionpool.py", line 449, in _make_request
    six.raise_from(e, None)
  File "<string>", line 3, in raise_from
  File "/home/airflow/.local/lib/python3.7/site-packages/urllib3/connectionpool.py", line 444, in _make_request
    httplib_response = conn.getresponse()
  File "/usr/local/lib/python3.7/http/client.py", line 1373, in getresponse
    response.begin()
  File "/usr/local/lib/python3.7/http/client.py", line 319, in begin
    version, status, reason = self._read_status()
  File "/usr/local/lib/python3.7/http/client.py", line 288, in _read_status
    raise RemoteDisconnected("Remote end closed connection without"
urllib3.exceptions.ProtocolError: ('Connection aborted.', RemoteDisconnected('Remote end closed connection without response'))
[2023-01-23T14:35:03.160+0000] {taskinstance.py:1323} INFO - Marking task as UP_FOR_RETRY. dag_id=data_extraction_and_loading_3, task_id=extract_data, execution_date=20220124T000000, start_date=20230123T143024, end_date=20230123T143503
[2023-01-23T14:35:03.419+0000] {standard_task_runner.py:105} ERROR - Failed to execute job 69 for task extract_data (('Connection aborted.', RemoteDisconnected('Remote end closed connection without response')); 1506)
[2023-01-23T14:35:03.768+0000] {local_task_job.py:208} INFO - Task exited with return code 1
[2023-01-23T14:35:04.044+0000] {taskinstance.py:2578} INFO - 0 downstream tasks scheduled from follow-on schedule check
