[2023-01-29T19:57:31.600+0000] {taskinstance.py:1083} INFO - Dependencies all met for <TaskInstance: data_pipeline.extract_data manual__2023-01-29T19:57:22.697430+00:00 [queued]>
[2023-01-29T19:57:31.618+0000] {taskinstance.py:1083} INFO - Dependencies all met for <TaskInstance: data_pipeline.extract_data manual__2023-01-29T19:57:22.697430+00:00 [queued]>
[2023-01-29T19:57:31.618+0000] {taskinstance.py:1279} INFO - 
--------------------------------------------------------------------------------
[2023-01-29T19:57:31.618+0000] {taskinstance.py:1280} INFO - Starting attempt 1 of 3
[2023-01-29T19:57:31.618+0000] {taskinstance.py:1281} INFO - 
--------------------------------------------------------------------------------
[2023-01-29T19:57:31.645+0000] {taskinstance.py:1300} INFO - Executing <Task(PythonOperator): extract_data> on 2023-01-29 19:57:22.697430+00:00
[2023-01-29T19:57:31.657+0000] {standard_task_runner.py:55} INFO - Started process 656 to run task
[2023-01-29T19:57:31.667+0000] {standard_task_runner.py:82} INFO - Running: ['***', 'tasks', 'run', 'data_pipeline', 'extract_data', 'manual__2023-01-29T19:57:22.697430+00:00', '--job-id', '4', '--raw', '--subdir', 'DAGS_FOLDER/etl_dag.py', '--cfg-path', '/tmp/tmpgvllfg7b']
[2023-01-29T19:57:31.671+0000] {standard_task_runner.py:83} INFO - Job 4: Subtask extract_data
[2023-01-29T19:57:31.707+0000] {logging_mixin.py:137} WARNING - /home/***/.local/lib/python3.7/site-packages/***/settings.py:249 DeprecationWarning: The sql_alchemy_conn option in [core] has been moved to the sql_alchemy_conn option in [database] - the old setting has been used, but please update your config.
[2023-01-29T19:57:31.787+0000] {task_command.py:388} INFO - Running <TaskInstance: data_pipeline.extract_data manual__2023-01-29T19:57:22.697430+00:00 [running]> on host 84fb6dd1372f
[2023-01-29T19:57:31.941+0000] {taskinstance.py:1509} INFO - Exporting the following env vars:
AIRFLOW_CTX_DAG_OWNER=abdessamad
AIRFLOW_CTX_DAG_ID=data_pipeline
AIRFLOW_CTX_TASK_ID=extract_data
AIRFLOW_CTX_EXECUTION_DATE=2023-01-29T19:57:22.697430+00:00
AIRFLOW_CTX_TRY_NUMBER=1
AIRFLOW_CTX_DAG_RUN_ID=manual__2023-01-29T19:57:22.697430+00:00
[2023-01-29T19:58:00.002+0000] {etl.py:120} ERROR - Error
[2023-01-29T19:58:00.056+0000] {etl.py:120} ERROR - Error
[2023-01-29T19:58:00.144+0000] {etl.py:120} ERROR - Error
[2023-01-29T19:58:00.234+0000] {etl.py:120} ERROR - Error
[2023-01-29T19:58:00.302+0000] {etl.py:120} ERROR - Error
[2023-01-29T19:58:00.376+0000] {etl.py:120} ERROR - Error
[2023-01-29T19:58:30.697+0000] {logging_mixin.py:137} INFO - mongo_db:27017: [Errno -3] Temporary failure in name resolution, Timeout: 30s, Topology Description: <TopologyDescription id: 63d6cface629225ca5d29acc, topology_type: Unknown, servers: [<ServerDescription ('mongo_db', 27017) server_type: Unknown, rtt: None, error=AutoReconnect('mongo_db:27017: [Errno -3] Temporary failure in name resolution')>]>
[2023-01-29T19:59:00.827+0000] {logging_mixin.py:137} INFO - mongo_db:27017: [Errno -3] Temporary failure in name resolution, Timeout: 30s, Topology Description: <TopologyDescription id: 63d6cface629225ca5d29acc, topology_type: Unknown, servers: [<ServerDescription ('mongo_db', 27017) server_type: Unknown, rtt: None, error=AutoReconnect('mongo_db:27017: [Errno -3] Temporary failure in name resolution')>]>
[2023-01-29T19:59:30.960+0000] {logging_mixin.py:137} INFO - mongo_db:27017: [Errno -3] Temporary failure in name resolution, Timeout: 30s, Topology Description: <TopologyDescription id: 63d6cface629225ca5d29acc, topology_type: Unknown, servers: [<ServerDescription ('mongo_db', 27017) server_type: Unknown, rtt: None, error=AutoReconnect('mongo_db:27017: [Errno -3] Temporary failure in name resolution')>]>
[2023-01-29T20:00:01.127+0000] {logging_mixin.py:137} INFO - mongo_db:27017: [Errno -3] Temporary failure in name resolution, Timeout: 30s, Topology Description: <TopologyDescription id: 63d6cface629225ca5d29acc, topology_type: Unknown, servers: [<ServerDescription ('mongo_db', 27017) server_type: Unknown, rtt: None, error=AutoReconnect('mongo_db:27017: [Errno -3] Temporary failure in name resolution')>]>
[2023-01-29T20:00:31.243+0000] {logging_mixin.py:137} INFO - mongo_db:27017: [Errno -3] Temporary failure in name resolution, Timeout: 30s, Topology Description: <TopologyDescription id: 63d6cface629225ca5d29acc, topology_type: Unknown, servers: [<ServerDescription ('mongo_db', 27017) server_type: Unknown, rtt: None, error=AutoReconnect('mongo_db:27017: [Errno -3] Temporary failure in name resolution')>]>
[2023-01-29T20:01:01.374+0000] {logging_mixin.py:137} INFO - mongo_db:27017: [Errno -3] Temporary failure in name resolution, Timeout: 30s, Topology Description: <TopologyDescription id: 63d6cface629225ca5d29acc, topology_type: Unknown, servers: [<ServerDescription ('mongo_db', 27017) server_type: Unknown, rtt: None, error=AutoReconnect('mongo_db:27017: [Errno -3] Temporary failure in name resolution')>]>
[2023-01-29T20:01:31.444+0000] {logging_mixin.py:137} INFO - mongo_db:27017: [Errno -3] Temporary failure in name resolution, Timeout: 30s, Topology Description: <TopologyDescription id: 63d6cface629225ca5d29acc, topology_type: Unknown, servers: [<ServerDescription ('mongo_db', 27017) server_type: Unknown, rtt: None, error=AutoReconnect('mongo_db:27017: [Errno -3] Temporary failure in name resolution')>]>
[2023-01-29T20:02:01.523+0000] {logging_mixin.py:137} INFO - mongo_db:27017: [Errno -3] Temporary failure in name resolution, Timeout: 30s, Topology Description: <TopologyDescription id: 63d6cface629225ca5d29acc, topology_type: Unknown, servers: [<ServerDescription ('mongo_db', 27017) server_type: Unknown, rtt: None, error=AutoReconnect('mongo_db:27017: [Errno -3] Temporary failure in name resolution')>]>
[2023-01-29T20:02:31.617+0000] {logging_mixin.py:137} INFO - mongo_db:27017: [Errno -3] Temporary failure in name resolution, Timeout: 30s, Topology Description: <TopologyDescription id: 63d6cface629225ca5d29acc, topology_type: Unknown, servers: [<ServerDescription ('mongo_db', 27017) server_type: Unknown, rtt: None, error=AutoReconnect('mongo_db:27017: [Errno -3] Temporary failure in name resolution')>]>
[2023-01-29T20:02:31.860+0000] {python.py:177} INFO - Done. Returned value was: None
[2023-01-29T20:02:31.898+0000] {taskinstance.py:1323} INFO - Marking task as SUCCESS. dag_id=data_pipeline, task_id=extract_data, execution_date=20230129T195722, start_date=20230129T195731, end_date=20230129T200231
[2023-01-29T20:02:31.955+0000] {local_task_job.py:208} INFO - Task exited with return code 0
[2023-01-29T20:02:32.016+0000] {taskinstance.py:2578} INFO - 1 downstream tasks scheduled from follow-on schedule check
